[2025-03-17T15:11:29.492+0600] {local_task_job_runner.py:123} INFO - ::group::Pre task execution logs
[2025-03-17T15:11:29.537+0600] {taskinstance.py:2614} INFO - Dependencies all met for dep_context=non-requeueable deps ti=<TaskInstance: etl_airflow_rest_api_dag.create_table scheduled__2025-03-10T04:00:00+00:00 [queued]>
[2025-03-17T15:11:29.555+0600] {taskinstance.py:2614} INFO - Dependencies all met for dep_context=requeueable deps ti=<TaskInstance: etl_airflow_rest_api_dag.create_table scheduled__2025-03-10T04:00:00+00:00 [queued]>
[2025-03-17T15:11:29.556+0600] {taskinstance.py:2867} INFO - Starting attempt 1 of 1
[2025-03-17T15:11:29.583+0600] {taskinstance.py:2890} INFO - Executing <Task(SQLExecuteQueryOperator): create_table> on 2025-03-10 04:00:00+00:00
[2025-03-17T15:11:29.601+0600] {standard_task_runner.py:104} INFO - Running: ['airflow', 'tasks', 'run', 'etl_airflow_rest_api_dag', 'create_table', 'scheduled__2025-03-10T04:00:00+00:00', '--job-id', '15', '--raw', '--subdir', 'DAGS_FOLDER/etl_airflow_rest_api_open_weather_data.py', '--cfg-path', '/tmp/tmpbgqnz98j']
[2025-03-17T15:11:29.603+0600] {standard_task_runner.py:105} INFO - Job 15: Subtask create_table
[2025-03-17T15:11:29.609+0600] {logging_mixin.py:190} WARNING - /home/shamim/airflow_venv/lib/python3.12/site-packages/airflow/task/task_runner/standard_task_runner.py:70 DeprecationWarning: This process (pid=20526) is multi-threaded, use of fork() may lead to deadlocks in the child.
[2025-03-17T15:11:29.611+0600] {standard_task_runner.py:72} INFO - Started process 20534 to run task
[2025-03-17T15:11:29.682+0600] {task_command.py:467} INFO - Running <TaskInstance: etl_airflow_rest_api_dag.create_table scheduled__2025-03-10T04:00:00+00:00 [running]> on host shamim-X541UV
[2025-03-17T15:11:29.800+0600] {taskinstance.py:3134} INFO - Exporting env vars: AIRFLOW_CTX_DAG_OWNER='airflow' AIRFLOW_CTX_DAG_ID='etl_airflow_rest_api_dag' AIRFLOW_CTX_TASK_ID='create_table' AIRFLOW_CTX_EXECUTION_DATE='2025-03-10T04:00:00+00:00' AIRFLOW_CTX_TRY_NUMBER='1' AIRFLOW_CTX_DAG_RUN_ID='scheduled__2025-03-10T04:00:00+00:00'
[2025-03-17T15:11:29.803+0600] {logging_mixin.py:190} INFO - Task instance is in running state
[2025-03-17T15:11:29.803+0600] {logging_mixin.py:190} INFO -  Previous state of the Task instance: queued
[2025-03-17T15:11:29.804+0600] {logging_mixin.py:190} INFO - Current task name:create_table state:running start_date:2025-03-17 09:11:29.538411+00:00
[2025-03-17T15:11:29.804+0600] {logging_mixin.py:190} INFO - Dag name:etl_airflow_rest_api_dag and current dag run status:running
[2025-03-17T15:11:29.805+0600] {taskinstance.py:732} INFO - ::endgroup::
[2025-03-17T15:11:29.806+0600] {sql.py:295} INFO - Executing: 
        DROP TABLE IF EXISTS weather_data_api CASCADE;
        CREATE TABLE IF NOT EXISTS weather_data_api(
            city VARCHAR(50),
            temperature NUMERIC(10,2),
            humidity NUMERIC(10,2),
            timestamp TIMESTAMP DEFAULT CURRENT_TIMESTAMP
        );
    
[2025-03-17T15:11:29.816+0600] {base.py:84} INFO - Retrieving connection 'postgres'
[2025-03-17T15:11:29.823+0600] {base.py:84} INFO - Retrieving connection 'postgres'
[2025-03-17T15:11:29.883+0600] {taskinstance.py:3313} ERROR - Task failed with exception
Traceback (most recent call last):
  File "/home/shamim/airflow_venv/lib/python3.12/site-packages/airflow/models/taskinstance.py", line 768, in _execute_task
    result = _execute_callable(context=context, **execute_callable_kwargs)
             ^^^^^^^^^^^^^^^^^^^^^^^^^^^^^^^^^^^^^^^^^^^^^^^^^^^^^^^^^^^^^
  File "/home/shamim/airflow_venv/lib/python3.12/site-packages/airflow/models/taskinstance.py", line 734, in _execute_callable
    return ExecutionCallableRunner(
           ^^^^^^^^^^^^^^^^^^^^^^^^
  File "/home/shamim/airflow_venv/lib/python3.12/site-packages/airflow/utils/operator_helpers.py", line 252, in run
    return self.func(*args, **kwargs)
           ^^^^^^^^^^^^^^^^^^^^^^^^^^
  File "/home/shamim/airflow_venv/lib/python3.12/site-packages/airflow/models/baseoperator.py", line 424, in wrapper
    return func(self, *args, **kwargs)
           ^^^^^^^^^^^^^^^^^^^^^^^^^^^
  File "/home/shamim/airflow_venv/lib/python3.12/site-packages/airflow/providers/common/sql/operators/sql.py", line 301, in execute
    output = hook.run(
             ^^^^^^^^^
  File "/home/shamim/airflow_venv/lib/python3.12/site-packages/airflow/providers/common/sql/hooks/sql.py", line 576, in run
    with self._create_autocommit_connection(autocommit) as conn:
  File "/usr/lib/python3.12/contextlib.py", line 137, in __enter__
    return next(self.gen)
           ^^^^^^^^^^^^^^
  File "/home/shamim/airflow_venv/lib/python3.12/site-packages/airflow/providers/common/sql/hooks/sql.py", line 684, in _create_autocommit_connection
    with closing(self.get_conn()) as conn:
                 ^^^^^^^^^^^^^^^
  File "/home/shamim/airflow_venv/lib/python3.12/site-packages/airflow/providers/postgres/hooks/postgres.py", line 174, in get_conn
    self.conn = psycopg2.connect(**conn_args)
                ^^^^^^^^^^^^^^^^^^^^^^^^^^^^^
  File "/home/shamim/airflow_venv/lib/python3.12/site-packages/psycopg2/__init__.py", line 122, in connect
    conn = _connect(dsn, connection_factory=connection_factory, **kwasync)
           ^^^^^^^^^^^^^^^^^^^^^^^^^^^^^^^^^^^^^^^^^^^^^^^^^^^^^^^^^^^^^^^
psycopg2.OperationalError: connection to server at "localhost" (127.0.0.1), port 5432 failed: FATAL:  password authentication failed for user "admin"
connection to server at "localhost" (127.0.0.1), port 5432 failed: FATAL:  password authentication failed for user "admin"

[2025-03-17T15:11:29.897+0600] {logging_mixin.py:190} INFO - Task instance in failure state
[2025-03-17T15:11:29.897+0600] {logging_mixin.py:190} INFO - Task start:2025-03-17 09:11:29.538411+00:00 end:2025-03-17 09:11:29.896473+00:00 duration:0.358062
[2025-03-17T15:11:29.898+0600] {logging_mixin.py:190} INFO - Task:<Task(SQLExecuteQueryOperator): create_table> dag:<DAG: etl_airflow_rest_api_dag> dagrun:<DagRun etl_airflow_rest_api_dag @ 2025-03-10 04:00:00+00:00: scheduled__2025-03-10T04:00:00+00:00, state:running, queued_at: 2025-03-17 09:10:58.315744+00:00. externally triggered: False>
[2025-03-17T15:11:29.899+0600] {logging_mixin.py:190} INFO - Failure caused by connection to server at "localhost" (127.0.0.1), port 5432 failed: FATAL:  password authentication failed for user "admin"
connection to server at "localhost" (127.0.0.1), port 5432 failed: FATAL:  password authentication failed for user "admin"
[2025-03-17T15:11:29.899+0600] {taskinstance.py:1226} INFO - Marking task as FAILED. dag_id=etl_airflow_rest_api_dag, task_id=create_table, run_id=scheduled__2025-03-10T04:00:00+00:00, execution_date=20250310T040000, start_date=20250317T091129, end_date=20250317T091129
[2025-03-17T15:11:29.932+0600] {taskinstance.py:341} INFO - ::group::Post task execution logs
[2025-03-17T15:11:29.933+0600] {standard_task_runner.py:124} ERROR - Failed to execute job 15 for task create_table (connection to server at "localhost" (127.0.0.1), port 5432 failed: FATAL:  password authentication failed for user "admin"
connection to server at "localhost" (127.0.0.1), port 5432 failed: FATAL:  password authentication failed for user "admin"
; 20534)
Traceback (most recent call last):
  File "/home/shamim/airflow_venv/lib/python3.12/site-packages/airflow/task/task_runner/standard_task_runner.py", line 117, in _start_by_fork
    ret = args.func(args, dag=self.dag)
          ^^^^^^^^^^^^^^^^^^^^^^^^^^^^^
  File "/home/shamim/airflow_venv/lib/python3.12/site-packages/airflow/cli/cli_config.py", line 49, in command
    return func(*args, **kwargs)
           ^^^^^^^^^^^^^^^^^^^^^
  File "/home/shamim/airflow_venv/lib/python3.12/site-packages/airflow/utils/cli.py", line 116, in wrapper
    return f(*args, **kwargs)
           ^^^^^^^^^^^^^^^^^^
  File "/home/shamim/airflow_venv/lib/python3.12/site-packages/airflow/cli/commands/task_command.py", line 483, in task_run
    task_return_code = _run_task_by_selected_method(args, _dag, ti)
                       ^^^^^^^^^^^^^^^^^^^^^^^^^^^^^^^^^^^^^^^^^^^^
  File "/home/shamim/airflow_venv/lib/python3.12/site-packages/airflow/cli/commands/task_command.py", line 256, in _run_task_by_selected_method
    return _run_raw_task(args, ti)
           ^^^^^^^^^^^^^^^^^^^^^^^
  File "/home/shamim/airflow_venv/lib/python3.12/site-packages/airflow/cli/commands/task_command.py", line 341, in _run_raw_task
    return ti._run_raw_task(
           ^^^^^^^^^^^^^^^^^
  File "/home/shamim/airflow_venv/lib/python3.12/site-packages/airflow/utils/session.py", line 97, in wrapper
    return func(*args, session=session, **kwargs)
           ^^^^^^^^^^^^^^^^^^^^^^^^^^^^^^^^^^^^^^
  File "/home/shamim/airflow_venv/lib/python3.12/site-packages/airflow/models/taskinstance.py", line 3006, in _run_raw_task
    return _run_raw_task(
           ^^^^^^^^^^^^^^
  File "/home/shamim/airflow_venv/lib/python3.12/site-packages/airflow/models/taskinstance.py", line 274, in _run_raw_task
    TaskInstance._execute_task_with_callbacks(
  File "/home/shamim/airflow_venv/lib/python3.12/site-packages/airflow/models/taskinstance.py", line 3161, in _execute_task_with_callbacks
    result = self._execute_task(context, task_orig)
             ^^^^^^^^^^^^^^^^^^^^^^^^^^^^^^^^^^^^^^
  File "/home/shamim/airflow_venv/lib/python3.12/site-packages/airflow/models/taskinstance.py", line 3185, in _execute_task
    return _execute_task(self, context, task_orig)
           ^^^^^^^^^^^^^^^^^^^^^^^^^^^^^^^^^^^^^^^
  File "/home/shamim/airflow_venv/lib/python3.12/site-packages/airflow/models/taskinstance.py", line 768, in _execute_task
    result = _execute_callable(context=context, **execute_callable_kwargs)
             ^^^^^^^^^^^^^^^^^^^^^^^^^^^^^^^^^^^^^^^^^^^^^^^^^^^^^^^^^^^^^
  File "/home/shamim/airflow_venv/lib/python3.12/site-packages/airflow/models/taskinstance.py", line 734, in _execute_callable
    return ExecutionCallableRunner(
           ^^^^^^^^^^^^^^^^^^^^^^^^
  File "/home/shamim/airflow_venv/lib/python3.12/site-packages/airflow/utils/operator_helpers.py", line 252, in run
    return self.func(*args, **kwargs)
           ^^^^^^^^^^^^^^^^^^^^^^^^^^
  File "/home/shamim/airflow_venv/lib/python3.12/site-packages/airflow/models/baseoperator.py", line 424, in wrapper
    return func(self, *args, **kwargs)
           ^^^^^^^^^^^^^^^^^^^^^^^^^^^
  File "/home/shamim/airflow_venv/lib/python3.12/site-packages/airflow/providers/common/sql/operators/sql.py", line 301, in execute
    output = hook.run(
             ^^^^^^^^^
  File "/home/shamim/airflow_venv/lib/python3.12/site-packages/airflow/providers/common/sql/hooks/sql.py", line 576, in run
    with self._create_autocommit_connection(autocommit) as conn:
  File "/usr/lib/python3.12/contextlib.py", line 137, in __enter__
    return next(self.gen)
           ^^^^^^^^^^^^^^
  File "/home/shamim/airflow_venv/lib/python3.12/site-packages/airflow/providers/common/sql/hooks/sql.py", line 684, in _create_autocommit_connection
    with closing(self.get_conn()) as conn:
                 ^^^^^^^^^^^^^^^
  File "/home/shamim/airflow_venv/lib/python3.12/site-packages/airflow/providers/postgres/hooks/postgres.py", line 174, in get_conn
    self.conn = psycopg2.connect(**conn_args)
                ^^^^^^^^^^^^^^^^^^^^^^^^^^^^^
  File "/home/shamim/airflow_venv/lib/python3.12/site-packages/psycopg2/__init__.py", line 122, in connect
    conn = _connect(dsn, connection_factory=connection_factory, **kwasync)
           ^^^^^^^^^^^^^^^^^^^^^^^^^^^^^^^^^^^^^^^^^^^^^^^^^^^^^^^^^^^^^^^
psycopg2.OperationalError: connection to server at "localhost" (127.0.0.1), port 5432 failed: FATAL:  password authentication failed for user "admin"
connection to server at "localhost" (127.0.0.1), port 5432 failed: FATAL:  password authentication failed for user "admin"

[2025-03-17T15:11:29.993+0600] {local_task_job_runner.py:266} INFO - Task exited with return code 1
[2025-03-17T15:11:30.032+0600] {taskinstance.py:3901} INFO - 0 downstream tasks scheduled from follow-on schedule check
[2025-03-17T15:11:30.043+0600] {local_task_job_runner.py:245} INFO - ::endgroup::
