[2025-03-17T15:11:59.552+0600] {local_task_job_runner.py:123} INFO - ::group::Pre task execution logs
[2025-03-17T15:11:59.579+0600] {taskinstance.py:2614} INFO - Dependencies all met for dep_context=non-requeueable deps ti=<TaskInstance: etl_airflow_rest_api_dag.create_table manual__2025-03-17T09:11:28.491308+00:00 [queued]>
[2025-03-17T15:11:59.595+0600] {taskinstance.py:2614} INFO - Dependencies all met for dep_context=requeueable deps ti=<TaskInstance: etl_airflow_rest_api_dag.create_table manual__2025-03-17T09:11:28.491308+00:00 [queued]>
[2025-03-17T15:11:59.596+0600] {taskinstance.py:2867} INFO - Starting attempt 1 of 1
[2025-03-17T15:11:59.617+0600] {taskinstance.py:2890} INFO - Executing <Task(SQLExecuteQueryOperator): create_table> on 2025-03-17 09:11:28.491308+00:00
[2025-03-17T15:11:59.637+0600] {standard_task_runner.py:104} INFO - Running: ['airflow', 'tasks', 'run', 'etl_airflow_rest_api_dag', 'create_table', 'manual__2025-03-17T09:11:28.491308+00:00', '--job-id', '20', '--raw', '--subdir', 'DAGS_FOLDER/etl_airflow_rest_api_open_weather_data.py', '--cfg-path', '/tmp/tmp5cm514j3']
[2025-03-17T15:11:59.640+0600] {standard_task_runner.py:105} INFO - Job 20: Subtask create_table
[2025-03-17T15:11:59.648+0600] {logging_mixin.py:190} WARNING - /home/shamim/airflow_venv/lib/python3.12/site-packages/airflow/task/task_runner/standard_task_runner.py:70 DeprecationWarning: This process (pid=20581) is multi-threaded, use of fork() may lead to deadlocks in the child.
[2025-03-17T15:11:59.650+0600] {standard_task_runner.py:72} INFO - Started process 20589 to run task
[2025-03-17T15:11:59.698+0600] {task_command.py:467} INFO - Running <TaskInstance: etl_airflow_rest_api_dag.create_table manual__2025-03-17T09:11:28.491308+00:00 [running]> on host shamim-X541UV
[2025-03-17T15:11:59.795+0600] {taskinstance.py:3134} INFO - Exporting env vars: AIRFLOW_CTX_DAG_OWNER='airflow' AIRFLOW_CTX_DAG_ID='etl_airflow_rest_api_dag' AIRFLOW_CTX_TASK_ID='create_table' AIRFLOW_CTX_EXECUTION_DATE='2025-03-17T09:11:28.491308+00:00' AIRFLOW_CTX_TRY_NUMBER='1' AIRFLOW_CTX_DAG_RUN_ID='manual__2025-03-17T09:11:28.491308+00:00'
[2025-03-17T15:11:59.797+0600] {logging_mixin.py:190} INFO - Task instance is in running state
[2025-03-17T15:11:59.798+0600] {logging_mixin.py:190} INFO -  Previous state of the Task instance: queued
[2025-03-17T15:11:59.798+0600] {logging_mixin.py:190} INFO - Current task name:create_table state:running start_date:2025-03-17 09:11:59.579729+00:00
[2025-03-17T15:11:59.798+0600] {logging_mixin.py:190} INFO - Dag name:etl_airflow_rest_api_dag and current dag run status:running
[2025-03-17T15:11:59.799+0600] {taskinstance.py:732} INFO - ::endgroup::
[2025-03-17T15:11:59.799+0600] {sql.py:295} INFO - Executing: 
        DROP TABLE IF EXISTS weather_data_api CASCADE;
        CREATE TABLE IF NOT EXISTS weather_data_api(
            city VARCHAR(50),
            temperature NUMERIC(10,2),
            humidity NUMERIC(10,2),
            timestamp TIMESTAMP DEFAULT CURRENT_TIMESTAMP
        );
    
[2025-03-17T15:11:59.810+0600] {base.py:84} INFO - Retrieving connection 'postgres'
[2025-03-17T15:11:59.815+0600] {base.py:84} INFO - Retrieving connection 'postgres'
[2025-03-17T15:11:59.862+0600] {taskinstance.py:3313} ERROR - Task failed with exception
Traceback (most recent call last):
  File "/home/shamim/airflow_venv/lib/python3.12/site-packages/airflow/models/taskinstance.py", line 768, in _execute_task
    result = _execute_callable(context=context, **execute_callable_kwargs)
             ^^^^^^^^^^^^^^^^^^^^^^^^^^^^^^^^^^^^^^^^^^^^^^^^^^^^^^^^^^^^^
  File "/home/shamim/airflow_venv/lib/python3.12/site-packages/airflow/models/taskinstance.py", line 734, in _execute_callable
    return ExecutionCallableRunner(
           ^^^^^^^^^^^^^^^^^^^^^^^^
  File "/home/shamim/airflow_venv/lib/python3.12/site-packages/airflow/utils/operator_helpers.py", line 252, in run
    return self.func(*args, **kwargs)
           ^^^^^^^^^^^^^^^^^^^^^^^^^^
  File "/home/shamim/airflow_venv/lib/python3.12/site-packages/airflow/models/baseoperator.py", line 424, in wrapper
    return func(self, *args, **kwargs)
           ^^^^^^^^^^^^^^^^^^^^^^^^^^^
  File "/home/shamim/airflow_venv/lib/python3.12/site-packages/airflow/providers/common/sql/operators/sql.py", line 301, in execute
    output = hook.run(
             ^^^^^^^^^
  File "/home/shamim/airflow_venv/lib/python3.12/site-packages/airflow/providers/common/sql/hooks/sql.py", line 576, in run
    with self._create_autocommit_connection(autocommit) as conn:
  File "/usr/lib/python3.12/contextlib.py", line 137, in __enter__
    return next(self.gen)
           ^^^^^^^^^^^^^^
  File "/home/shamim/airflow_venv/lib/python3.12/site-packages/airflow/providers/common/sql/hooks/sql.py", line 684, in _create_autocommit_connection
    with closing(self.get_conn()) as conn:
                 ^^^^^^^^^^^^^^^
  File "/home/shamim/airflow_venv/lib/python3.12/site-packages/airflow/providers/postgres/hooks/postgres.py", line 174, in get_conn
    self.conn = psycopg2.connect(**conn_args)
                ^^^^^^^^^^^^^^^^^^^^^^^^^^^^^
  File "/home/shamim/airflow_venv/lib/python3.12/site-packages/psycopg2/__init__.py", line 122, in connect
    conn = _connect(dsn, connection_factory=connection_factory, **kwasync)
           ^^^^^^^^^^^^^^^^^^^^^^^^^^^^^^^^^^^^^^^^^^^^^^^^^^^^^^^^^^^^^^^
psycopg2.OperationalError: connection to server at "localhost" (127.0.0.1), port 5432 failed: FATAL:  password authentication failed for user "admin"
connection to server at "localhost" (127.0.0.1), port 5432 failed: FATAL:  password authentication failed for user "admin"

[2025-03-17T15:11:59.874+0600] {logging_mixin.py:190} INFO - Task instance in failure state
[2025-03-17T15:11:59.874+0600] {logging_mixin.py:190} INFO - Task start:2025-03-17 09:11:59.579729+00:00 end:2025-03-17 09:11:59.873642+00:00 duration:0.293913
[2025-03-17T15:11:59.875+0600] {logging_mixin.py:190} INFO - Task:<Task(SQLExecuteQueryOperator): create_table> dag:<DAG: etl_airflow_rest_api_dag> dagrun:<DagRun etl_airflow_rest_api_dag @ 2025-03-17 09:11:28.491308+00:00: manual__2025-03-17T09:11:28.491308+00:00, state:running, queued_at: 2025-03-17 09:11:28.507394+00:00. externally triggered: True>
[2025-03-17T15:11:59.875+0600] {logging_mixin.py:190} INFO - Failure caused by connection to server at "localhost" (127.0.0.1), port 5432 failed: FATAL:  password authentication failed for user "admin"
connection to server at "localhost" (127.0.0.1), port 5432 failed: FATAL:  password authentication failed for user "admin"
[2025-03-17T15:11:59.876+0600] {taskinstance.py:1226} INFO - Marking task as FAILED. dag_id=etl_airflow_rest_api_dag, task_id=create_table, run_id=manual__2025-03-17T09:11:28.491308+00:00, execution_date=20250317T091128, start_date=20250317T091159, end_date=20250317T091159
[2025-03-17T15:12:00.268+0600] {taskinstance.py:341} INFO - ::group::Post task execution logs
[2025-03-17T15:12:00.269+0600] {standard_task_runner.py:124} ERROR - Failed to execute job 20 for task create_table (connection to server at "localhost" (127.0.0.1), port 5432 failed: FATAL:  password authentication failed for user "admin"
connection to server at "localhost" (127.0.0.1), port 5432 failed: FATAL:  password authentication failed for user "admin"
; 20589)
Traceback (most recent call last):
  File "/home/shamim/airflow_venv/lib/python3.12/site-packages/airflow/task/task_runner/standard_task_runner.py", line 117, in _start_by_fork
    ret = args.func(args, dag=self.dag)
          ^^^^^^^^^^^^^^^^^^^^^^^^^^^^^
  File "/home/shamim/airflow_venv/lib/python3.12/site-packages/airflow/cli/cli_config.py", line 49, in command
    return func(*args, **kwargs)
           ^^^^^^^^^^^^^^^^^^^^^
  File "/home/shamim/airflow_venv/lib/python3.12/site-packages/airflow/utils/cli.py", line 116, in wrapper
    return f(*args, **kwargs)
           ^^^^^^^^^^^^^^^^^^
  File "/home/shamim/airflow_venv/lib/python3.12/site-packages/airflow/cli/commands/task_command.py", line 483, in task_run
    task_return_code = _run_task_by_selected_method(args, _dag, ti)
                       ^^^^^^^^^^^^^^^^^^^^^^^^^^^^^^^^^^^^^^^^^^^^
  File "/home/shamim/airflow_venv/lib/python3.12/site-packages/airflow/cli/commands/task_command.py", line 256, in _run_task_by_selected_method
    return _run_raw_task(args, ti)
           ^^^^^^^^^^^^^^^^^^^^^^^
  File "/home/shamim/airflow_venv/lib/python3.12/site-packages/airflow/cli/commands/task_command.py", line 341, in _run_raw_task
    return ti._run_raw_task(
           ^^^^^^^^^^^^^^^^^
  File "/home/shamim/airflow_venv/lib/python3.12/site-packages/airflow/utils/session.py", line 97, in wrapper
    return func(*args, session=session, **kwargs)
           ^^^^^^^^^^^^^^^^^^^^^^^^^^^^^^^^^^^^^^
  File "/home/shamim/airflow_venv/lib/python3.12/site-packages/airflow/models/taskinstance.py", line 3006, in _run_raw_task
    return _run_raw_task(
           ^^^^^^^^^^^^^^
  File "/home/shamim/airflow_venv/lib/python3.12/site-packages/airflow/models/taskinstance.py", line 274, in _run_raw_task
    TaskInstance._execute_task_with_callbacks(
  File "/home/shamim/airflow_venv/lib/python3.12/site-packages/airflow/models/taskinstance.py", line 3161, in _execute_task_with_callbacks
    result = self._execute_task(context, task_orig)
             ^^^^^^^^^^^^^^^^^^^^^^^^^^^^^^^^^^^^^^
  File "/home/shamim/airflow_venv/lib/python3.12/site-packages/airflow/models/taskinstance.py", line 3185, in _execute_task
    return _execute_task(self, context, task_orig)
           ^^^^^^^^^^^^^^^^^^^^^^^^^^^^^^^^^^^^^^^
  File "/home/shamim/airflow_venv/lib/python3.12/site-packages/airflow/models/taskinstance.py", line 768, in _execute_task
    result = _execute_callable(context=context, **execute_callable_kwargs)
             ^^^^^^^^^^^^^^^^^^^^^^^^^^^^^^^^^^^^^^^^^^^^^^^^^^^^^^^^^^^^^
  File "/home/shamim/airflow_venv/lib/python3.12/site-packages/airflow/models/taskinstance.py", line 734, in _execute_callable
    return ExecutionCallableRunner(
           ^^^^^^^^^^^^^^^^^^^^^^^^
  File "/home/shamim/airflow_venv/lib/python3.12/site-packages/airflow/utils/operator_helpers.py", line 252, in run
    return self.func(*args, **kwargs)
           ^^^^^^^^^^^^^^^^^^^^^^^^^^
  File "/home/shamim/airflow_venv/lib/python3.12/site-packages/airflow/models/baseoperator.py", line 424, in wrapper
    return func(self, *args, **kwargs)
           ^^^^^^^^^^^^^^^^^^^^^^^^^^^
  File "/home/shamim/airflow_venv/lib/python3.12/site-packages/airflow/providers/common/sql/operators/sql.py", line 301, in execute
    output = hook.run(
             ^^^^^^^^^
  File "/home/shamim/airflow_venv/lib/python3.12/site-packages/airflow/providers/common/sql/hooks/sql.py", line 576, in run
    with self._create_autocommit_connection(autocommit) as conn:
  File "/usr/lib/python3.12/contextlib.py", line 137, in __enter__
    return next(self.gen)
           ^^^^^^^^^^^^^^
  File "/home/shamim/airflow_venv/lib/python3.12/site-packages/airflow/providers/common/sql/hooks/sql.py", line 684, in _create_autocommit_connection
    with closing(self.get_conn()) as conn:
                 ^^^^^^^^^^^^^^^
  File "/home/shamim/airflow_venv/lib/python3.12/site-packages/airflow/providers/postgres/hooks/postgres.py", line 174, in get_conn
    self.conn = psycopg2.connect(**conn_args)
                ^^^^^^^^^^^^^^^^^^^^^^^^^^^^^
  File "/home/shamim/airflow_venv/lib/python3.12/site-packages/psycopg2/__init__.py", line 122, in connect
    conn = _connect(dsn, connection_factory=connection_factory, **kwasync)
           ^^^^^^^^^^^^^^^^^^^^^^^^^^^^^^^^^^^^^^^^^^^^^^^^^^^^^^^^^^^^^^^
psycopg2.OperationalError: connection to server at "localhost" (127.0.0.1), port 5432 failed: FATAL:  password authentication failed for user "admin"
connection to server at "localhost" (127.0.0.1), port 5432 failed: FATAL:  password authentication failed for user "admin"

[2025-03-17T15:12:00.319+0600] {local_task_job_runner.py:266} INFO - Task exited with return code 1
[2025-03-17T15:12:00.461+0600] {taskinstance.py:3901} INFO - 0 downstream tasks scheduled from follow-on schedule check
[2025-03-17T15:12:00.476+0600] {local_task_job_runner.py:245} INFO - ::endgroup::
